ROUTE START provider=openai file=eucalypt-woodland-open-dry-forest-generate-an-aboriginal-dot-painting-of-an-australian-eucalypt-wood-aab54e9a.png
Using temporary uploaded file /home/art/art-processing/unanalysed-artwork/unanalysed-02/eucalypt-woodland-open-dry-forest-generate-an-aboriginal-dot-painting-of-an-australian-eucalypt-wood-aab54e9a.png
Traceback (most recent call last):
  File "/home/art/routes/artwork_routes.py", line 207, in _run_ai_analysis
    return json.loads(result.stdout)
           ^^^^^^^^^^^^^^^^^^^^^^^^^
  File "/usr/lib/python3.11/json/__init__.py", line 346, in loads
    return _default_decoder.decode(s)
           ^^^^^^^^^^^^^^^^^^^^^^^^^^
  File "/usr/lib/python3.11/json/decoder.py", line 337, in decode
    obj, end = self.raw_decode(s, idx=_w(s, 0).end())
               ^^^^^^^^^^^^^^^^^^^^^^^^^^^^^^^^^^^^^^
  File "/usr/lib/python3.11/json/decoder.py", line 355, in raw_decode
    raise JSONDecodeError("Expecting value", s, err.value) from None
json.decoder.JSONDecodeError: Expecting value: line 1 column 2 (char 1)

During handling of the above exception, another exception occurred:

Traceback (most recent call last):
  File "/home/art/routes/artwork_routes.py", line 1643, in analyze_api
    entry = _run_ai_analysis(temp_file, provider)
            ^^^^^^^^^^^^^^^^^^^^^^^^^^^^^^^^^^^^^
  File "/home/art/routes/artwork_routes.py", line 210, in _run_ai_analysis
    raise RuntimeError("AI analysis output could not be parsed.")
RuntimeError: AI analysis output could not be parsed.

ROUTE START provider=openai file=quokka-generate-an-aboriginal-dot-painting-of-a-quokka-setonix-brachyurus-smiling-and-standing-uprig-a2d377e8.jpg
Using temporary uploaded file /home/art/art-processing/unanalysed-artwork/unanalysed-03/quokka-generate-an-aboriginal-dot-painting-of-a-quokka-setonix-brachyurus-smiling-and-standing-uprig-a2d377e8.jpg
Traceback (most recent call last):
  File "/home/art/routes/artwork_routes.py", line 207, in _run_ai_analysis
    return json.loads(result.stdout)
           ^^^^^^^^^^^^^^^^^^^^^^^^^
  File "/usr/lib/python3.11/json/__init__.py", line 346, in loads
    return _default_decoder.decode(s)
           ^^^^^^^^^^^^^^^^^^^^^^^^^^
  File "/usr/lib/python3.11/json/decoder.py", line 337, in decode
    obj, end = self.raw_decode(s, idx=_w(s, 0).end())
               ^^^^^^^^^^^^^^^^^^^^^^^^^^^^^^^^^^^^^^
  File "/usr/lib/python3.11/json/decoder.py", line 355, in raw_decode
    raise JSONDecodeError("Expecting value", s, err.value) from None
json.decoder.JSONDecodeError: Expecting value: line 1 column 2 (char 1)

During handling of the above exception, another exception occurred:

Traceback (most recent call last):
  File "/home/art/routes/artwork_routes.py", line 1643, in analyze_api
    entry = _run_ai_analysis(temp_file, provider)
            ^^^^^^^^^^^^^^^^^^^^^^^^^^^^^^^^^^^^^
  File "/home/art/routes/artwork_routes.py", line 210, in _run_ai_analysis
    raise RuntimeError("AI analysis output could not be parsed.")
RuntimeError: AI analysis output could not be parsed.

