2025-07-22 11:02 | user: robbie | action: analyse-openai | file: fern-gully-with-creek-flow-generate-an-aboriginal-dot-painting-of-a-fern-gully-with-a-small-creek-ru-1-c4d8b34f.jpg | status: fail | detail: analysis failed | error: AI analysis output could not be parsed.
Traceback (most recent call last):
  File "/home/art/art/routes/artwork_routes.py", line 194, in _run_ai_analysis
    return json.loads(result.stdout)
           ^^^^^^^^^^^^^^^^^^^^^^^^^
  File "/usr/lib/python3.11/json/__init__.py", line 346, in loads
    return _default_decoder.decode(s)
           ^^^^^^^^^^^^^^^^^^^^^^^^^^
  File "/usr/lib/python3.11/json/decoder.py", line 337, in decode
    obj, end = self.raw_decode(s, idx=_w(s, 0).end())
               ^^^^^^^^^^^^^^^^^^^^^^^^^^^^^^^^^^^^^^
  File "/usr/lib/python3.11/json/decoder.py", line 355, in raw_decode
    raise JSONDecodeError("Expecting value", s, err.value) from None
json.decoder.JSONDecodeError: Expecting value: line 1 column 2 (char 1)

During handling of the above exception, another exception occurred:

Traceback (most recent call last):
  File "/home/art/art/routes/artwork_routes.py", line 1622, in analyze_api
    entry = _run_ai_analysis(temp_file, provider)
            ^^^^^^^^^^^^^^^^^^^^^^^^^^^^^^^^^^^^^
  File "/home/art/art/routes/artwork_routes.py", line 197, in _run_ai_analysis
    raise RuntimeError("AI analysis output could not be parsed.")
RuntimeError: AI analysis output could not be parsed.

2025-07-22 11:02 | user: robbie | action: analyse-openai | file: fern-gully-with-creek-flow-generate-an-aboriginal-dot-painting-of-a-fern-gully-with-a-small-creek-ru-1-c4d8b34f.jpg | status: fail | detail: analysis failed | error: AI analysis output could not be parsed.
Traceback (most recent call last):
  File "/home/art/art/routes/artwork_routes.py", line 194, in _run_ai_analysis
    return json.loads(result.stdout)
           ^^^^^^^^^^^^^^^^^^^^^^^^^
  File "/usr/lib/python3.11/json/__init__.py", line 346, in loads
    return _default_decoder.decode(s)
           ^^^^^^^^^^^^^^^^^^^^^^^^^^
  File "/usr/lib/python3.11/json/decoder.py", line 337, in decode
    obj, end = self.raw_decode(s, idx=_w(s, 0).end())
               ^^^^^^^^^^^^^^^^^^^^^^^^^^^^^^^^^^^^^^
  File "/usr/lib/python3.11/json/decoder.py", line 355, in raw_decode
    raise JSONDecodeError("Expecting value", s, err.value) from None
json.decoder.JSONDecodeError: Expecting value: line 1 column 2 (char 1)

During handling of the above exception, another exception occurred:

Traceback (most recent call last):
  File "/home/art/art/routes/artwork_routes.py", line 1664, in analyze_api
    entry = _run_ai_analysis(img_path, provider)
            ^^^^^^^^^^^^^^^^^^^^^^^^^^^^^^^^^^^^
  File "/home/art/art/routes/artwork_routes.py", line 197, in _run_ai_analysis
    raise RuntimeError("AI analysis output could not be parsed.")
RuntimeError: AI analysis output could not be parsed.

2025-07-22 11:05 | user: robbie | action: analyse-openai | file: coastal-dunes-at-sunset-generate-an-aboriginal-dot-painting-of-coastal-sand-dunes-at-sunset-showing-21696ef9.jpg | status: fail | detail: analysis failed | error: AI analysis output could not be parsed.
Traceback (most recent call last):
  File "/home/art/art/routes/artwork_routes.py", line 194, in _run_ai_analysis
    return json.loads(result.stdout)
           ^^^^^^^^^^^^^^^^^^^^^^^^^
  File "/usr/lib/python3.11/json/__init__.py", line 346, in loads
    return _default_decoder.decode(s)
           ^^^^^^^^^^^^^^^^^^^^^^^^^^
  File "/usr/lib/python3.11/json/decoder.py", line 337, in decode
    obj, end = self.raw_decode(s, idx=_w(s, 0).end())
               ^^^^^^^^^^^^^^^^^^^^^^^^^^^^^^^^^^^^^^
  File "/usr/lib/python3.11/json/decoder.py", line 355, in raw_decode
    raise JSONDecodeError("Expecting value", s, err.value) from None
json.decoder.JSONDecodeError: Expecting value: line 1 column 2 (char 1)

During handling of the above exception, another exception occurred:

Traceback (most recent call last):
  File "/home/art/art/routes/artwork_routes.py", line 1622, in analyze_api
    entry = _run_ai_analysis(temp_file, provider)
            ^^^^^^^^^^^^^^^^^^^^^^^^^^^^^^^^^^^^^
  File "/home/art/art/routes/artwork_routes.py", line 197, in _run_ai_analysis
    raise RuntimeError("AI analysis output could not be parsed.")
RuntimeError: AI analysis output could not be parsed.

