2025-07-23 06:04 | user: robbie | action: analyse-openai | file: cassowary-generate-an-aboriginal-dot-painting-of-a-southern-cassowary-casuarius-casuarius-featuring-7d4402b1.jpg | status: fail | detail: analysis failed | error: AI analysis output could not be parsed.
Traceback (most recent call last):
  File "/home/art/routes/artwork_routes.py", line 207, in _run_ai_analysis
    return json.loads(result.stdout)
           ^^^^^^^^^^^^^^^^^^^^^^^^^
  File "/usr/lib/python3.11/json/__init__.py", line 346, in loads
    return _default_decoder.decode(s)
           ^^^^^^^^^^^^^^^^^^^^^^^^^^
  File "/usr/lib/python3.11/json/decoder.py", line 337, in decode
    obj, end = self.raw_decode(s, idx=_w(s, 0).end())
               ^^^^^^^^^^^^^^^^^^^^^^^^^^^^^^^^^^^^^^
  File "/usr/lib/python3.11/json/decoder.py", line 355, in raw_decode
    raise JSONDecodeError("Expecting value", s, err.value) from None
json.decoder.JSONDecodeError: Expecting value: line 1 column 2 (char 1)

During handling of the above exception, another exception occurred:

Traceback (most recent call last):
  File "/home/art/routes/artwork_routes.py", line 1643, in analyze_api
    entry = _run_ai_analysis(temp_file, provider)
            ^^^^^^^^^^^^^^^^^^^^^^^^^^^^^^^^^^^^^
  File "/home/art/routes/artwork_routes.py", line 210, in _run_ai_analysis
    raise RuntimeError("AI analysis output could not be parsed.")
RuntimeError: AI analysis output could not be parsed.

2025-07-23 06:08 | user: robbie | action: analyse-openai | file: coastal-dunes-at-sunset-generate-an-aboriginal-dot-painting-of-coastal-sand-dunes-at-sunset-showing-98610d92.jpg | status: fail | detail: analysis failed | error: AI analysis output could not be parsed.
Traceback (most recent call last):
  File "/home/art/routes/artwork_routes.py", line 207, in _run_ai_analysis
    return json.loads(result.stdout)
           ^^^^^^^^^^^^^^^^^^^^^^^^^
  File "/usr/lib/python3.11/json/__init__.py", line 346, in loads
    return _default_decoder.decode(s)
           ^^^^^^^^^^^^^^^^^^^^^^^^^^
  File "/usr/lib/python3.11/json/decoder.py", line 337, in decode
    obj, end = self.raw_decode(s, idx=_w(s, 0).end())
               ^^^^^^^^^^^^^^^^^^^^^^^^^^^^^^^^^^^^^^
  File "/usr/lib/python3.11/json/decoder.py", line 355, in raw_decode
    raise JSONDecodeError("Expecting value", s, err.value) from None
json.decoder.JSONDecodeError: Expecting value: line 1 column 2 (char 1)

During handling of the above exception, another exception occurred:

Traceback (most recent call last):
  File "/home/art/routes/artwork_routes.py", line 1643, in analyze_api
    entry = _run_ai_analysis(temp_file, provider)
            ^^^^^^^^^^^^^^^^^^^^^^^^^^^^^^^^^^^^^
  File "/home/art/routes/artwork_routes.py", line 210, in _run_ai_analysis
    raise RuntimeError("AI analysis output could not be parsed.")
RuntimeError: AI analysis output could not be parsed.

2025-07-23 06:09 | user: robbie | action: analyse-openai | file: eucalypt-woodland-open-dry-forest-generate-an-aboriginal-dot-painting-of-an-australian-eucalypt-wood-1-b3b79971.jpg | status: fail | detail: analysis failed | error: AI analysis output could not be parsed.
Traceback (most recent call last):
  File "/home/art/routes/artwork_routes.py", line 207, in _run_ai_analysis
    return json.loads(result.stdout)
           ^^^^^^^^^^^^^^^^^^^^^^^^^
  File "/usr/lib/python3.11/json/__init__.py", line 346, in loads
    return _default_decoder.decode(s)
           ^^^^^^^^^^^^^^^^^^^^^^^^^^
  File "/usr/lib/python3.11/json/decoder.py", line 337, in decode
    obj, end = self.raw_decode(s, idx=_w(s, 0).end())
               ^^^^^^^^^^^^^^^^^^^^^^^^^^^^^^^^^^^^^^
  File "/usr/lib/python3.11/json/decoder.py", line 355, in raw_decode
    raise JSONDecodeError("Expecting value", s, err.value) from None
json.decoder.JSONDecodeError: Expecting value: line 1 column 2 (char 1)

During handling of the above exception, another exception occurred:

Traceback (most recent call last):
  File "/home/art/routes/artwork_routes.py", line 1643, in analyze_api
    entry = _run_ai_analysis(temp_file, provider)
            ^^^^^^^^^^^^^^^^^^^^^^^^^^^^^^^^^^^^^
  File "/home/art/routes/artwork_routes.py", line 210, in _run_ai_analysis
    raise RuntimeError("AI analysis output could not be parsed.")
RuntimeError: AI analysis output could not be parsed.

2025-07-23 06:14 | user: robbie | action: analyse-openai | file: tawny-frogmouth-generate-an-aboriginal-dot-painting-of-a-tawny-frogmouth-podargus-strigoides-perched-2c7aa2df.jpg | status: fail | detail: analysis failed | error: AI analysis output could not be parsed.
Traceback (most recent call last):
  File "/home/art/routes/artwork_routes.py", line 207, in _run_ai_analysis
    return json.loads(result.stdout)
           ^^^^^^^^^^^^^^^^^^^^^^^^^
  File "/usr/lib/python3.11/json/__init__.py", line 346, in loads
    return _default_decoder.decode(s)
           ^^^^^^^^^^^^^^^^^^^^^^^^^^
  File "/usr/lib/python3.11/json/decoder.py", line 337, in decode
    obj, end = self.raw_decode(s, idx=_w(s, 0).end())
               ^^^^^^^^^^^^^^^^^^^^^^^^^^^^^^^^^^^^^^
  File "/usr/lib/python3.11/json/decoder.py", line 355, in raw_decode
    raise JSONDecodeError("Expecting value", s, err.value) from None
json.decoder.JSONDecodeError: Expecting value: line 1 column 2 (char 1)

During handling of the above exception, another exception occurred:

Traceback (most recent call last):
  File "/home/art/routes/artwork_routes.py", line 1643, in analyze_api
    entry = _run_ai_analysis(temp_file, provider)
            ^^^^^^^^^^^^^^^^^^^^^^^^^^^^^^^^^^^^^
  File "/home/art/routes/artwork_routes.py", line 210, in _run_ai_analysis
    raise RuntimeError("AI analysis output could not be parsed.")
RuntimeError: AI analysis output could not be parsed.

